<mujoco model="CDPR">

  <compiler angle="radian" meshdir="assets" autolimits="true"/>
  <option timestep="0.002" iterations="10" solver="Newton" tolerance="1e-8" gravity="0 0 -9.81" cone="elliptic" impratio="5"/>
  

  <asset>
    <!-- Define the missing 'grid' material -->
    <texture name="grid" type="2d" builtin="checker" width="512" height="512" rgb1="0.1 0.1 0.1" rgb2="0.9 0.9 0.9"/>
    <material name="grid" texture="grid" texrepeat="1 1" texuniform="true"/>
    
    <!-- Materials for the cables -->
    <material name="red_cable" rgba="1 0 0 1"/>
    <material name="green_cable" rgba="0 1 0 1"/>
    <material name="blue_cable" rgba="0 0 1 1"/>
    <material name="yellow_cable" rgba="1 1 0 1"/>

    <!-- Material for the cage -->
    <material name="cage_material" rgba="0.5 0.5 0.5 1"/>

     <material name="metal" rgba="0.58 0.58 0.58 1"/>
    <material name="silicone" rgba="0.1882 0.1882 0.1882 1"/>
    <material name="gray" rgba="0.4627 0.4627 0.4627 1"/>
    <material name="black" rgba="0.149 0.149 0.149 1"/>

    <mesh class="2f85" file="base_mount.stl"/>
    <mesh class="2f85" file="base.stl"/>
    <mesh class="2f85" file="driver.stl"/>
    <mesh class="2f85" file="coupler.stl"/>
    <mesh class="2f85" file="follower.stl"/>
    <mesh class="2f85" file="pad.stl"/>
    <mesh class="2f85" file="silicone_pad.stl"/>
    <mesh class="2f85" file="spring_link.stl"/>

  </asset>
  
  
  <default>
    <default class="2f85">
      <mesh scale="0.001 0.001 0.001"/>
      <general biastype="affine"/>

      <joint axis="1 0 0"/>
      <default class="driver">
        <joint range="0 0.8" armature="0.005" damping="0.1" solimplimit="0.95 0.99 0.001" solreflimit="0.005 1"/>
      </default>
      <default class="follower">
        <joint range="-0.872664 0.872664" armature="0.001" pos="0 -0.018 0.0065" solimplimit="0.95 0.99 0.001" solreflimit="0.005 1"/>
      </default>
      <default class="spring_link">
        <joint range="-0.29670597283 0.8" armature="0.001" stiffness="0.05" springref="2.62" damping="0.00125"/>
      </default>
      <default class="coupler">
        <joint range="-1.57 0" armature="0.001" solimplimit="0.95 0.99 0.001" solreflimit="0.005 1"/>
      </default>

      <default class="visual">
        <geom type="mesh" contype="0" conaffinity="0" group="2" rgba="0.7 0.7 0.7 1"/>
      </default>
      <default class="collision">
        <geom type="mesh" group="3" solimp="0.9 0.95 0.001" solref="0.002 1"/>
        <default class="pad_box1">
          <geom mass="0" type="box" pos="0 -0.0026 0.028125" size="0.011 0.004 0.009375" friction="0.7"
            solimp="0.95 0.99 0.001" solref="0.004 1" priority="1" rgba="0.55 0.55 0.55 1"/>
        </default>
        <default class="pad_box2">
          <geom mass="0" type="box" pos="0 -0.0026 0.009375" size="0.011 0.004 0.009375" friction="0.6"
            solimp="0.95 0.99 0.001" solref="0.004 1" priority="1" rgba="0.45 0.45 0.45 1"/>
        </default>
      </default>
    </default>
  </default>
  

  <worldbody>
    <!-- Light and visual elements removed for minimal default appearance -->
    <geom type="plane" size="5 5 0.1" material="grid" rgba="0.7 0.7 0.7 1"/>

    <!-- Cage Structure -->
    <!-- Vertical Pillars -->
    <geom type="cylinder" size="0.02" fromto="-0.5 -0.23 0 -0.5 -0.23 0.6" material="cage_material"/>
    <geom type="cylinder" size="0.02" fromto="0.5 -0.23 0 0.5 -0.23 0.6" material="cage_material"/>
    <geom type="cylinder" size="0.02" fromto="-0.5 0.23 0 -0.5 0.23 0.6" material="cage_material"/>
    <geom type="cylinder" size="0.02" fromto="0.5 0.23 0 0.5 0.23 0.6" material="cage_material"/>

    <!-- Horizontal Beams (Top) -->
    <geom type="cylinder" size="0.02" fromto="-0.5 -0.23 0.6 0.5 -0.23 0.6" material="cage_material"/>
    <geom type="cylinder" size="0.02" fromto="-0.5 0.23 0.6 0.5 0.23 0.6" material="cage_material"/>
    <geom type="cylinder" size="0.02" fromto="-0.5 -0.23 0.6 -0.5 0.23 0.6" material="cage_material"/>
    <geom type="cylinder" size="0.02" fromto="0.5 -0.23 0.6 0.5 0.23 0.6" material="cage_material"/>

    <!-- Horizontal Beams (Bottom) -->
    <geom type="cylinder" size="0.02" fromto="-0.5 -0.23 0 0.5 -0.23 0" material="cage_material"/>
    <geom type="cylinder" size="0.02" fromto="-0.5 0.23 0 0.5 0.23 0" material="cage_material"/>
    <geom type="cylinder" size="0.02" fromto="-0.5 -0.23 0 -0.5 0.23 0" material="cage_material"/>
    <geom type="cylinder" size="0.02" fromto="0.5 -0.23 0 0.5 0.23 0" material="cage_material"/>


    

    <!-- Mobile Platform with 5cm Cube Size -->
    <body name="mobile_platform" pos="0 0 0.3">
      <freejoint/>
      <!-- Attachment sites at the four corners -->
      <!-- Top (upper) sites on the top face (z = +0.025) -->
      <site name="top1" pos="-0.025 -0.025  0.025" size="0.005"/>
      <site name="top2" pos=" 0.025 -0.025  0.025" size="0.005"/>
      <site name="top3" pos="-0.025  0.025  0.025" size="0.005"/>
      <site name="top4" pos=" 0.025  0.025  0.025" size="0.005"/>
      <!-- Bottom (lower) sites on the bottom face (z = -0.025) -->
      <site name="bottom1" pos="-0.025 -0.025  0.025" size="0.005"/>
      <site name="bottom2" pos=" 0.025 -0.025  0.025" size="0.005"/>
      <site name="bottom3" pos="-0.025  0.025  0.025" size="0.005"/>
      <site name="bottom4" pos=" 0.025  0.025  0.025" size="0.005"/>
      
      <!-- The box geom now has half-dimensions of 0.025 (i.e., full size 5cm x 5cm x 5cm) -->
      <geom type="box" size="0.025 0.025 0.025" mass="0.5" rgba="0.4 0.4 1 1"/>
    
      
      <!-- Laser Origin: at the center of the bottom face (z = -0.025 relative to the platform's center) -->
      <!-- <geom name="laser_ptr" type="capsule" pos="0 0 -0.30" quat="0.7071 0 0 0.7071" size="0.002 0.3" rgba="1 0 0 1" contype="0" conaffinity="0"/> -->
      
      <body name="base_mount" pos="0 0 0.007" quat="0 1 0 0" childclass="2f85">
      <geom class="visual" mesh="base_mount" material="black"/>
      <geom class="collision" mesh="base_mount"/>
      <body name="base" pos="0 0 0.0038" quat="1 0 0 -1">
        <inertial mass="0.777441" pos="0 -2.70394e-05 0.0354675" quat="1 -0.00152849 0 0"
          diaginertia="0.000260285 0.000225381 0.000152708"/>
        <geom class="visual" mesh="base" material="black"/>
        <geom class="collision" mesh="base"/>
        <site name="pinch" pos="0 0 0.145" type="sphere" group="5" rgba="0.9 0.9 0.9 1" size="0.005"/>
        <!-- Right-hand side 4-bar linkage -->
        <body name="right_driver" pos="0 0.0306011 0.054904">
          <inertial mass="0.00899563" pos="2.96931e-12 0.0177547 0.00107314" quat="0.681301 0.732003 0 0"
            diaginertia="1.72352e-06 1.60906e-06 3.22006e-07"/>
          <joint name="right_driver_joint" class="driver"/>
          <geom class="visual" mesh="driver" material="gray"/>
          <geom class="collision" mesh="driver"/>
          <body name="right_coupler" pos="0 0.0315 -0.0041">
            <inertial mass="0.0140974" pos="0 0.00301209 0.0232175" quat="0.705636 -0.0455904 0.0455904 0.705636"
              diaginertia="4.16206e-06 3.52216e-06 8.88131e-07"/>
            <joint name="right_coupler_joint" class="coupler"/>
            <geom class="visual" mesh="coupler" material="black"/>
            <geom class="collision" mesh="coupler"/>
          </body>
        </body>
        <body name="right_spring_link" pos="0 0.0132 0.0609">
          <inertial mass="0.0221642" pos="-8.65005e-09 0.0181624 0.0212658" quat="0.663403 -0.244737 0.244737 0.663403"
            diaginertia="8.96853e-06 6.71733e-06 2.63931e-06"/>
          <joint name="right_spring_link_joint" class="spring_link"/>
          <geom class="visual" mesh="spring_link" material="black"/>
          <geom class="collision" mesh="spring_link"/>
          <body name="right_follower" pos="0 0.055 0.0375">
            <inertial mass="0.0125222" pos="0 -0.011046 0.0124786" quat="1 0.1664 0 0"
              diaginertia="2.67415e-06 2.4559e-06 6.02031e-07"/>
            <joint name="right_follower_joint" class="follower"/>
            <geom class="visual" mesh="follower" material="black"/>
            <geom class="collision" mesh="follower"/>
            <body name="right_pad" pos="0 -0.0189 0.01352">
              <geom class="pad_box1" name="right_pad1"/>
              <geom class="pad_box2" name="right_pad2"/>
              <inertial mass="0.0035" pos="0 -0.0025 0.0185" quat="0.707107 0 0 0.707107"
                diaginertia="4.73958e-07 3.64583e-07 1.23958e-07"/>
              <geom class="visual" mesh="pad"/>
              <body name="right_silicone_pad">
                <geom class="visual" mesh="silicone_pad" material="black"/>
              </body>
            </body>
          </body>
        </body>
        <!-- Left-hand side 4-bar linkage -->
        <body name="left_driver" pos="0 -0.0306011 0.054904" quat="0 0 0 1">
          <inertial mass="0.00899563" pos="0 0.0177547 0.00107314" quat="0.681301 0.732003 0 0"
            diaginertia="1.72352e-06 1.60906e-06 3.22006e-07"/>
          <joint name="left_driver_joint" class="driver"/>
          <geom class="visual" mesh="driver" material="gray"/>
          <geom class="collision" mesh="driver"/>
          <body name="left_coupler" pos="0 0.0315 -0.0041">
            <inertial mass="0.0140974" pos="0 0.00301209 0.0232175" quat="0.705636 -0.0455904 0.0455904 0.705636"
              diaginertia="4.16206e-06 3.52216e-06 8.88131e-07"/>
            <joint name="left_coupler_joint" class="coupler"/>
            <geom class="visual" mesh="coupler" material="black"/>
            <geom class="collision" mesh="coupler"/>
          </body>
        </body>
        <body name="left_spring_link" pos="0 -0.0132 0.0609" quat="0 0 0 1">
          <inertial mass="0.0221642" pos="-8.65005e-09 0.0181624 0.0212658" quat="0.663403 -0.244737 0.244737 0.663403"
            diaginertia="8.96853e-06 6.71733e-06 2.63931e-06"/>
          <joint name="left_spring_link_joint" class="spring_link"/>
          <geom class="visual" mesh="spring_link" material="black"/>
          <geom class="collision" mesh="spring_link"/>
          <body name="left_follower" pos="0 0.055 0.0375">
            <inertial mass="0.0125222" pos="0 -0.011046 0.0124786" quat="1 0.1664 0 0"
              diaginertia="2.67415e-06 2.4559e-06 6.02031e-07"/>
            <joint name="left_follower_joint" class="follower"/>
            <geom class="visual" mesh="follower" material="black"/>
            <geom class="collision" mesh="follower"/>
            <body name="left_pad" pos="0 -0.0189 0.01352">
              <geom class="pad_box1" name="left_pad1"/>
              <geom class="pad_box2" name="left_pad2"/>
              <inertial mass="0.0035" pos="0 -0.0025 0.0185" quat="1 0 0 1"
                diaginertia="4.73958e-07 3.64583e-07 1.23958e-07"/>
              <geom class="visual" mesh="pad"/>
              <body name="left_silicone_pad">
                <geom class="visual" mesh="silicone_pad" material="black"/>
              </body>
            </body>
          </body>
        </body>
      </body>
    </body>
      

    </body>  

    <!-- Mobile Platform with 5cm Cube Size -->
    <body name="cube" pos="0 0 0.05">
      <freejoint/>
      <!-- The box geom now has half-dimensions of 0.025 (i.e., full size 5cm x 5cm x 5cm) -->
      <geom type="box" size="0.025 0.025 0.025" mass="0.5" rgba="0.4 0.4 1 1"/>
    </body>
    
    <!-- Motor Attachment Points -->
    <!-- Top motor anchors for top cables -->
    <site name="motor1_anchor" pos="-0.5 -0.23 0.6" size="0.01"/>
    <site name="motor2_anchor" pos=" 0.5 -0.23 0.6" size="0.01"/>
    <site name="motor3_anchor" pos="-0.5  0.23 0.6" size="0.01"/>
    <site name="motor4_anchor" pos=" 0.5  0.23 0.6" size="0.01"/>
    <!-- Bottom motor anchors for bottom cables -->
    <site name="motor5_anchor" pos="-0.5 -0.23 0.0" size="0.01"/>
    <site name="motor6_anchor" pos=" 0.5 -0.23 0.0" size="0.01"/>
    <site name="motor7_anchor" pos="-0.5  0.23 0.0" size="0.01"/>
    <site name="motor8_anchor" pos=" 0.5  0.23 0.0" size="0.01"/>


    
  </worldbody>

  <contact>
    <exclude body1="base" body2="left_driver"/>
    <exclude body1="base" body2="right_driver"/>
    <exclude body1="base" body2="left_spring_link"/>
    <exclude body1="base" body2="right_spring_link"/>
    <exclude body1="right_coupler" body2="right_follower"/>
    <exclude body1="left_coupler" body2="left_follower"/>
  </contact>

  <!-- Tendons for the 8 cables -->
  <tendon>
    <!-- Top frame cables: attach top motor anchors to bottom platform sites -->
    <spatial name="cable1" width="0.001" material="red_cable" 
             stiffness="500" damping="20" frictionloss="0.0" limited="true" range="0.0 2.0">
      <site site="motor1_anchor"/>
      <site site="bottom1"/>
    </spatial>
    <spatial name="cable2" width="0.001" material="green_cable" 
             stiffness="500" damping="20" frictionloss="0.0" limited="true" range="0.0 2.0">
      <site site="motor2_anchor"/>
      <site site="bottom2"/>
    </spatial>
    <spatial name="cable3" width="0.001" material="blue_cable" 
             stiffness="500" damping="20" frictionloss="0.0" limited="true" range="0.0 2.0">
      <site site="motor3_anchor"/>
      <site site="bottom3"/>
    </spatial>
    <spatial name="cable4" width="0.001" material="yellow_cable" 
             stiffness="500" damping="20" frictionloss="0.0" limited="true" range="0.0 2.0">
      <site site="motor4_anchor"/>
      <site site="bottom4"/>
    </spatial>
    <!-- Bottom frame cables: attach bottom motor anchors to top platform sites -->
    <spatial name="cable5" width="0.001" material="red_cable" 
             stiffness="500" damping="20" frictionloss="0.0" limited="true" range="0.0 2.0">
      <site site="motor5_anchor"/>
      <site site="top1"/>
    </spatial>
    <spatial name="cable6" width="0.001" material="green_cable" 
             stiffness="500" damping="20" frictionloss="0.0" limited="true" range="0.0 2.0">
      <site site="motor6_anchor"/>
      <site site="top2"/>
    </spatial>
    <spatial name="cable7" width="0.001" material="blue_cable" 
             stiffness="500" damping="20" frictionloss="0.0" limited="true" range="0.0 2.0">
      <site site="motor7_anchor"/>
      <site site="top3"/>
    </spatial>
    <spatial name="cable8" width="0.001" material="yellow_cable" 
             stiffness="500" damping="20" frictionloss="0.0" limited="true" range="0.0 2.0">
      <site site="motor8_anchor"/>
      <site site="top4"/>
    </spatial>

    <fixed name="split">
      <joint joint="right_driver_joint" coef="0.5"/>
      <joint joint="left_driver_joint" coef="0.5"/>
    </fixed>
     
 
  </tendon>



  <equality>
    <connect anchor="0 0 0" body1="right_follower" body2="right_coupler" solimp="0.95 0.99 0.001" solref="0.005 1"/>
    <connect anchor="0 0 0" body1="left_follower" body2="left_coupler" solimp="0.95 0.99 0.001" solref="0.005 1"/>
    <joint joint1="right_driver_joint" joint2="left_driver_joint" polycoef="0 1 0 0 0" solimp="0.95 0.99 0.001"
      solref="0.005 1"/>
  </equality>


 

  <actuator>
    <position name="actuator1" tendon="cable1" ctrlrange="0.00 1.0" kp="2000.0"/>
    <position name="actuator2" tendon="cable2" ctrlrange="0.00 1.0" kp="2000.0"/>
    <position name="actuator3" tendon="cable3" ctrlrange="0.00 1.0" kp="2000.0"/>
    <position name="actuator4" tendon="cable4" ctrlrange="0.00 1.0" kp="2000.0"/>
    <position name="actuator5" tendon="cable5" ctrlrange="0.00 1.0" kp="2000.0"/>
    <position name="actuator6" tendon="cable6" ctrlrange="0.00 1.0" kp="2000.0"/>
    <position name="actuator7" tendon="cable7" ctrlrange="0.00 1.0" kp="2000.0"/>
    <position name="actuator8" tendon="cable8" ctrlrange="0.00 1.0" kp="2000.0"/>


    <general class="2f85" name="fingers_actuator" tendon="split" forcerange="-5 5" ctrlrange="0 255"
      gainprm="0.3137255 0 0" biasprm="0 -100 -10"/>



  </actuator>


    <!-- <actuator>
    <velocity name="actuator1" tendon="cable1" ctrlrange="0.0 2.0" kv="100.0"/>
    <velocity name="actuator2" tendon="cable2" ctrlrange="0.0 2.0" kv="100.0"/>
    <velocity name="actuator3" tendon="cable3" ctrlrange="0.0 2.0" kv="100.0"/>
    <velocity name="actuator4" tendon="cable4" ctrlrange="0.0 2.0" kv="100.0"/>
    <velocity name="actuator5" tendon="cable5" ctrlrange="0.0 2.0" kv="100.0"/>
    <velocity name="actuator6" tendon="cable6" ctrlrange="0.0 2.0" kv="100.0"/>
    <velocity name="actuator7" tendon="cable7" ctrlrange="0.0 2.0" kv="100.0"/>
    <velocity name="actuator8" tendon="cable8" ctrlrange="0.0 2.0" kv="100.0"/>
  </actuator> -->






  <sensor>
    <tendonpos name="encoder1" tendon="cable1"/>
    <tendonpos name="encoder2" tendon="cable2"/>
    <tendonpos name="encoder3" tendon="cable3"/>
    <tendonpos name="encoder4" tendon="cable4"/>
    <tendonpos name="encoder5" tendon="cable5"/>
    <tendonpos name="encoder6" tendon="cable6"/>
    <tendonpos name="encoder7" tendon="cable7"/>
    <tendonpos name="encoder8" tendon="cable8"/>
    <framepos name="platform_pos" objtype="body" objname="mobile_platform"/>
    <framequat name="platform_rot" objtype="body" objname="mobile_platform"/>
    <framepos name="cube_pos" objtype="body" objname="cube"/>
    <framequat name="cube_rot" objtype="body" objname="cube"/>
  </sensor>
</mujoco>
